<?xml version="1.0" ?>
<!-- =================================================================================== -->
<!-- |    This document was autogenerated by xacro from sia20d_workspace.xacro         | -->
<!-- |    EDITING THIS FILE BY HAND IS NOT RECOMMENDED                                 | -->
<!-- =================================================================================== -->
<robot name="sia20d_workspace" xmlns:xacro="http://ros.org/wiki/xacro">
  <material name="yellow_transparent">
    <color rgba="0 1 1 0.4"/>
  </material>
  <material name="orange_transparent">
    <color rgba="1 0.5 0 0.4"/>
  </material>
  <material name="gray_transparent">
    <color rgba="0.6 0.6 0.6 0.4"/>
  </material>
  <material name="blue_transparent">
    <color rgba="0 0.8 1 0.4"/>
  </material>
  <link name="world_frame"/>
  <!-- property list -->
  <!--"0.087"-->
  <!-- instantiating workcell definitions -->
  <link name="table_base1">
    <visual>
      <origin rpy="0 0 0" xyz="0 0 -0.5"/>
      <geometry>
        <box size="1.3875 2.22 1"/>
      </geometry>
      <material name="orange_transparent"/>
    </visual>
    <collision>
      <origin rpy="0 0 0" xyz="0 0 -0.5"/>
      <geometry>
        <box size="1.3875 2.22 1"/>
      </geometry>
      <material name="blue_transparent"/>
    </collision>
  </link>
  <joint name="workcell_to_table_base1" type="fixed">
    <parent link="world_frame"/>
    <child link="table_base1"/>
    <origin rpy="0 0 0" xyz="0.69375 0 0"/>
  </joint>
  <link name="front_wall1">
    <visual>
      <geometry>
        <box size="0.1 2.22 1"/>
      </geometry>
      <material name="gray_transparent"/>
    </visual>
    <collision>
      <geometry>
        <box size="0.1 2.22 1"/>
      </geometry>
      <material name="blue_transparent"/>
    </collision>
  </link>
  <joint name="world_frame_to_front_wall1" type="fixed">
    <parent link="world_frame"/>
    <child link="front_wall1"/>
    <origin rpy="0 0 0" xyz="1.3375 0 0.5"/>
  </joint>
  <link name="back_wall1">
    <visual>
      <geometry>
        <box size="0.04 2.0 1"/>
      </geometry>
      <material name="gray_transparent"/>
    </visual>
    <collision>
      <geometry>
        <box size="0.04 2.0 1"/>
      </geometry>
      <material name="blue_transparent"/>
    </collision>
  </link>
  <joint name="world_frame_to_back_wall1" type="fixed">
    <parent link="world_frame"/>
    <child link="back_wall1"/>
    <origin rpy="0 0 0" xyz="0.02 0 0.5"/>
  </joint>
  <link name="left_wall1">
    <visual>
      <geometry>
        <box size="1.221 0.1 1"/>
      </geometry>
      <material name="gray_transparent"/>
    </visual>
    <collision>
      <geometry>
        <box size="1.221 0.1 1"/>
      </geometry>
      <material name="blue_transparent"/>
    </collision>
  </link>
  <joint name="world_frame_to_left_wall1" type="fixed">
    <parent link="world_frame"/>
    <child link="left_wall1"/>
    <origin rpy="0 0 0" xyz="0.687 1.06 0.5"/>
  </joint>
  <link name="right_wall1">
    <visual>
      <geometry>
        <box size="1.221 0.1 1"/>
      </geometry>
      <material name="gray_transparent"/>
    </visual>
    <collision>
      <geometry>
        <box size="1.221 0.1 1"/>
      </geometry>
      <material name="blue_transparent"/>
    </collision>
  </link>
  <joint name="world_frame_to_right_wall1" type="fixed">
    <parent link="world_frame"/>
    <child link="right_wall1"/>
    <origin rpy="0 0 0" xyz="0.687 -1.06 0.5"/>
  </joint>
  <link name="pole1">
    <visual>
      <geometry>
        <box size="0.09 0.09 1"/>
      </geometry>
      <material name="gray_transparent"/>
    </visual>
    <collision>
      <geometry>
        <box size="0.09 0.09 1"/>
      </geometry>
      <material name="blue_transparent"/>
    </collision>
  </link>
  <joint name="world_frame_to_pole1" type="fixed">
    <parent link="world_frame"/>
    <child link="pole1"/>
    <origin rpy="0 0 0" xyz="0.9465 -0.845 0.5"/>
  </joint>
  <!-- end of workcell definitions -->
  <link name="roof1">
    <collision>
      <geometry>
        <box size="1.40 2.220 0.04"/>
      </geometry>
    </collision>
  </link>
  <!-- instantiating sensor definitions -->
  <material name="color_b">
    <color rgba="0 0.8 1 0.4"/>
  </material>
  <material name="color_a">
    <color rgba="0.8 0.2 1 0.2"/>
  </material>
  <material name="silver">
    <color rgba="0.6 0.6 0.6 1"/>
  </material>
  <link name="kinect_link">
    <collision>
      <material name="color_a"/>
      <geometry>
        <box size="0.36 0.28 0.22"/>
      </geometry>
    </collision>
  </link>
  <link name="kinect_keepout">
    <!--collision>
<material name="${prefix}color_b"/>
<geometry>
<box size="0.2 0.32 ${z_val + 0.08}"/>
</geometry>
</collision-->
  </link>
  <link name="kinect_frame">
    <visual>
      <origin rpy="0 0 0" xyz="0 0 0"/>
      <geometry>
        <box size="0.064 0.28 0.04"/>
      </geometry>
      <material name="silver"/>
    </visual>
    <collision>
      <origin rpy="0 0 0" xyz="0 0 0"/>
      <geometry>
        <box size="0.064 0.28 0.04"/>
      </geometry>
    </collision>
  </link>
  <link name="kinect_ir_link">
    <visual>
      <origin rpy="0 0 0" xyz="0 0 0"/>
      <geometry>
        <sphere radius="0.0005"/>
      </geometry>
    </visual>
  </link>
  <link name="kinect_rgb_link">
    <visual>
      <origin rpy="0 0 0" xyz="0 0 0"/>
      <geometry>
        <sphere radius="0.0005"/>
      </geometry>
    </visual>
  </link>
  <link name="kinect_ir_optical_frame"/>
  <link name="kinect_rgb_optical_frame"/>
  <joint name="kinect_frame_joint" type="fixed">
    <parent link="kinect_link"/>
    <child link="kinect_frame"/>
    <origin rpy="0 0 0" xyz="0 0 0"/>
  </joint>
  <joint name="kinect_ir_joint" type="fixed">
    <parent link="kinect_frame"/>
    <child link="kinect_ir_link"/>
    <origin rpy="0 0 0" xyz="0 0 0"/>
  </joint>
  <joint name="kinect_ir_optical_frame_joint" type="fixed">
    <parent link="kinect_ir_link"/>
    <child link="kinect_ir_optical_frame"/>
    <origin rpy="-1.57 0 -1.57" xyz="0 0 0"/>
  </joint>
  <joint name="kinect_rgb_joint" type="fixed">
    <parent link="kinect_ir_link"/>
    <child link="kinect_rgb_link"/>
    <origin rpy="0 0 0" xyz="0 -0.03 0"/>
  </joint>
  <joint name="kinect_rgb_optical_frame_joint" type="fixed">
    <parent link="kinect_rgb_link"/>
    <child link="kinect_rgb_optical_frame"/>
    <origin rpy="-1.57 0 -1.57" xyz="0 0 0"/>
  </joint>
  <joint name="base_link_to_kinect_link" type="fixed">
    <parent link="base_link"/>
    <child link="kinect_link"/>
    <origin rpy="0.005 1.968 0.0" xyz="1.01 0.169 1.206"/>
  </joint>
  <joint name="base_link_to_kinect_keepout" type="fixed">
    <parent link="base_link"/>
    <child link="kinect_keepout"/>
    <origin rpy="0 0 0.0" xyz="1.01 0.169 0.643"/>
  </joint>
  <!-- end of sensor definitions -->
  <!-- instantiating arm  -->
  <link name="eff_frame"/>
  <link name="gripper_body">
    <visual>
      <geometry>
        <mesh filename="package://godel_robot_config/meshes/Deburring_eff.STL"/>
      </geometry>
      <material name="silver">
        <color rgba="0.8 0.8 0.8 1"/>
      </material>
    </visual>
    <collision>
      <geometry>
        <mesh filename="package://godel_robot_config/meshes/Deburring_eff_Collision_Model.STL"/>
      </geometry>
      <material name="another_blue2">
        <color rgba="0.38 0.54 0.83 1"/>
      </material>
    </collision>
  </link>
  <link name="tcp_frame"/>
  <link name="asus_mount"/>
  <material name="dark_silver">
    <color rgba="0.1 0.1 0.1 1"/>
  </material>
  <link name="asus_link"/>
  <link name="asus_frame">
    <visual>
      <origin rpy="0 0 0" xyz="0 0 0"/>
      <geometry>
        <box size="0.04 0.22 0.04"/>
      </geometry>
      <material name="dark_silver"/>
    </visual>
    <collision>
      <origin rpy="0 0 0" xyz="0 0 0"/>
      <geometry>
        <box size="0.04 0.22 0.04"/>
      </geometry>
    </collision>
  </link>
  <link name="asus_ir_link">
    <visual>
      <origin rpy="0 0 0" xyz="0 0 0"/>
      <geometry>
        <sphere radius="0.0005"/>
      </geometry>
    </visual>
  </link>
  <link name="asus_rgb_link">
    <visual>
      <origin rpy="0 0 0" xyz="0 0 0"/>
      <geometry>
        <sphere radius="0.0005"/>
      </geometry>
    </visual>
  </link>
  <link name="asus_ir_optical_frame"/>
  <link name="asus_rgb_optical_frame"/>
  <joint name="asus_frame_joint" type="fixed">
    <parent link="asus_link"/>
    <child link="asus_frame"/>
    <origin rpy="0 0 0" xyz="0 0 0"/>
  </joint>
  <joint name="asus_ir_joint" type="fixed">
    <parent link="asus_frame"/>
    <child link="asus_ir_link"/>
    <origin rpy="0 0 0" xyz="0 0.0476 0"/>
  </joint>
  <joint name="asus_ir_optical_frame_joint" type="fixed">
    <parent link="asus_ir_link"/>
    <child link="asus_ir_optical_frame"/>
    <origin rpy="-1.57 0 -1.57" xyz="0 0 0"/>
  </joint>
  <joint name="asus_rgb_joint" type="fixed">
    <parent link="asus_ir_link"/>
    <child link="asus_rgb_link"/>
    <origin rpy="0 0 0" xyz="0 -0.025 0"/>
  </joint>
  <joint name="asus_rgb_optical_frame_joint" type="fixed">
    <parent link="asus_rgb_link"/>
    <child link="asus_rgb_optical_frame"/>
    <origin rpy="-1.57 0 -1.57" xyz="0 0 0"/>
  </joint>
  <joint name="asus_mount_to_asus_link" type="fixed">
    <parent link="asus_mount"/>
    <child link="asus_link"/>
    <origin rpy="-3.123031 0.001618 0.02739" xyz="0.01479 0.006741 0.007162"/>
  </joint>
  <joint name="gripper_to_palm" type="fixed">
    <parent link="eff_frame"/>
    <child link="gripper_body"/>
    <origin rpy="0 0 3.6651914" xyz="0 0 0.0"/>
  </joint>
  <joint name="eff_frame_to_asus_mount" type="fixed">
    <parent link="eff_frame"/>
    <child link="asus_mount"/>
    <origin rpy="3.14 0 2.09" xyz="0 0 0.150"/>
  </joint>
  <joint name="gripper_to_tcp" type="fixed">
    <parent link="gripper_body"/>
    <child link="tcp_frame"/>
    <origin rpy="0 0 0" xyz="0.2 0 0.05"/>
  </joint>
  <link name="base_link">
    <visual>
      <geometry>
        <mesh filename="package://motoman_sia20d_support/meshes/sia20d/visual/MOTOMAN_BASE.stl"/>
      </geometry>
      <material name="blue">
        <color rgba="0 0 1 1"/>
      </material>
    </visual>
    <collision>
      <geometry>
        <mesh filename="package://motoman_sia20d_support/meshes/sia20d/collision/MOTOMAN_BASE.stl"/>
      </geometry>
      <material name="yellow">
        <color rgba="0 1 1 1"/>
      </material>
    </collision>
  </link>
  <link name="link_s">
    <visual>
      <origin rpy="0 0 3.1416" xyz="0 0 0"/>
      <geometry>
        <mesh filename="package://motoman_sia20d_support/meshes/sia20d/visual/MOTOMAN_AXIS_S.stl"/>
      </geometry>
      <material name="silver">
        <color rgba="0.8 0.8 0.8 1"/>
      </material>
    </visual>
    <collision>
      <origin rpy="0 0 3.1416" xyz="0 0 0"/>
      <geometry>
        <mesh filename="package://motoman_sia20d_support/meshes/sia20d/collision/MOTOMAN_AXIS_S.stl"/>
      </geometry>
      <material name="yellow"/>
    </collision>
  </link>
  <link name="link_l">
    <visual>
      <origin rpy="1.57 3.1416 3.1416" xyz="0 0 0"/>
      <geometry>
        <mesh filename="package://motoman_sia20d_support/meshes/sia20d/visual/MOTOMAN_AXIS_L.stl"/>
      </geometry>
      <material name="blue"/>
    </visual>
    <collision>
      <origin rpy="1.57 3.1416 3.1416" xyz="0 0 0"/>
      <geometry>
        <mesh filename="package://motoman_sia20d_support/meshes/sia20d/collision/MOTOMAN_AXIS_L.stl"/>
      </geometry>
      <material name="yellow"/>
    </collision>
  </link>
  <link name="link_e">
    <visual>
      <origin rpy="0 0 0" xyz="0 0 0"/>
      <geometry>
        <mesh filename="package://motoman_sia20d_support/meshes/sia20d/visual/MOTOMAN_AXIS_E.stl"/>
      </geometry>
      <material name="silver"/>
    </visual>
    <collision>
      <origin rpy="0 0 0" xyz="0 0 0"/>
      <geometry>
        <mesh filename="package://motoman_sia20d_support/meshes/sia20d/collision/MOTOMAN_AXIS_E.stl"/>
      </geometry>
      <material name="yellow"/>
    </collision>
  </link>
  <link name="link_u">
    <visual>
      <origin rpy="1.57 -3.1415 3.1416" xyz="0 0 0"/>
      <geometry>
        <mesh filename="package://motoman_sia20d_support/meshes/sia20d/visual/MOTOMAN_AXIS_U.stl"/>
      </geometry>
      <material name="blue"/>
    </visual>
    <collision>
      <origin rpy="1.57 -3.1415 3.1416" xyz="0 0 0"/>
      <geometry>
        <mesh filename="package://motoman_sia20d_support/meshes/sia20d/collision/MOTOMAN_AXIS_U.stl"/>
      </geometry>
      <material name="yellow"/>
    </collision>
  </link>
  <link name="link_r">
    <visual>
      <origin rpy="0 0 0" xyz="0 0 0"/>
      <geometry>
        <mesh filename="package://motoman_sia20d_support/meshes/sia20d/visual/MOTOMAN_AXIS_R.stl"/>
      </geometry>
      <material name="silver"/>
    </visual>
    <collision>
      <origin rpy="0 0 0" xyz="0 0 0"/>
      <geometry>
        <mesh filename="package://motoman_sia20d_support/meshes/sia20d/collision/MOTOMAN_AXIS_R.stl"/>
      </geometry>
      <material name="yellow"/>
    </collision>
  </link>
  <link name="link_b">
    <visual>
      <origin rpy="-1.57 0 0" xyz="0 0 0"/>
      <geometry>
        <mesh filename="package://motoman_sia20d_support/meshes/sia20d/visual/MOTOMAN_AXIS_B.stl"/>
      </geometry>
      <material name="blue"/>
    </visual>
    <collision>
      <origin rpy="-1.57 0 0" xyz="0 0 0"/>
      <geometry>
        <mesh filename="package://motoman_sia20d_support/meshes/sia20d/collision/MOTOMAN_AXIS_B.stl"/>
      </geometry>
      <material name="yellow"/>
    </collision>
  </link>
  <link name="link_t">
    <visual>
      <geometry>
        <mesh filename="package://motoman_sia20d_support/meshes/sia20d/visual/MOTOMAN_AXIS_T.stl"/>
      </geometry>
      <material name="silver"/>
    </visual>
    <collision>
      <geometry>
        <mesh filename="package://motoman_sia20d_support/meshes/sia20d/collision/MOTOMAN_AXIS_T.stl"/>
      </geometry>
      <material name="yellow"/>
    </collision>
  </link>
  <link name="tool0"/>
  <joint name="joint_s" type="revolute">
    <parent link="base_link"/>
    <child link="link_s"/>
    <origin rpy="0 0 0" xyz="0 0 0.41"/>
    <axis xyz="0 0 1"/>
    <limit effort="100" lower="-3.1416" upper="3.1416" velocity="2.26"/>
  </joint>
  <joint name="joint_l" type="revolute">
    <parent link="link_s"/>
    <child link="link_l"/>
    <origin rpy="0 0 0" xyz="0 0 0"/>
    <axis xyz="0 1 0"/>
    <limit effort="100" lower="-1.91" upper="1.91" velocity="2.26"/>
  </joint>
  <joint name="joint_e" type="revolute">
    <parent link="link_l"/>
    <child link="link_e"/>
    <origin rpy="0 0 0" xyz="0 0 0.49"/>
    <axis xyz="0 0 1"/>
    <limit effort="100" lower="-2.96" upper="2.96" velocity="2.96"/>
  </joint>
  <joint name="joint_u" type="revolute">
    <parent link="link_e"/>
    <child link="link_u"/>
    <origin rpy="0 0 0" xyz="0 0 0"/>
    <axis xyz="0 -1 0"/>
    <limit effort="100" lower="-2.26" upper="2.26" velocity="2.96"/>
  </joint>
  <joint name="joint_r" type="revolute">
    <parent link="link_u"/>
    <child link="link_r"/>
    <origin rpy="0 0 0" xyz="0 0 0.420"/>
    <axis xyz="0 0 -1"/>
    <limit effort="100" lower="-3.1416" upper="3.1416" velocity="3.48"/>
  </joint>
  <joint name="joint_b" type="revolute">
    <parent link="link_r"/>
    <child link="link_b"/>
    <origin rpy="0 0 0" xyz="0 0 0"/>
    <axis xyz="0 -1 0"/>
    <limit effort="100" lower="-1.91" upper="1.91" velocity="3.48"/>
  </joint>
  <joint name="joint_t" type="revolute">
    <parent link="link_b"/>
    <child link="link_t"/>
    <origin rpy="0 0 0" xyz="0 0 0.18"/>
    <axis xyz="0 0 -1"/>
    <limit effort="100" lower="-3.1416" upper="3.1416" velocity="6.97"/>
  </joint>
  <joint name="link_t-tool0" type="fixed">
    <origin rpy="0 0 -3.1416" xyz="0 0 0.0"/>
    <parent link="link_t"/>
    <child link="tool0"/>
  </joint>
  <joint name="link_t_to_eff" type="fixed">
    <parent link="link_t"/>
    <child link="eff_frame"/>
    <origin rpy="0.0 0.0 0.0" xyz="0 0.0 0"/>
  </joint>
  <!-- start of arm-workcell joint definitions -->
  <joint name="world_to_base" type="fixed">
    <parent link="world_frame"/>
    <child link="base_link"/>
    <origin rpy="0 0 0" xyz="0.241 0 0"/>
  </joint>
  <joint name="world_to_roof1" type="fixed">
    <parent link="world_frame"/>
    <child link="roof1"/>
    <origin rpy="0 0 0" xyz="0.65 0 1.32"/>
  </joint>
  <!-- end of arm-workcell joint definitions -->
</robot>

